[Sun Feb 23 14:47:35 2014] [error] [client 127.0.0.1] mod_wsgi (pid=8972): Exception occurred processing WSGI script '/home/base_project/engine/wsgi.py'.
[Sun Feb 23 14:47:35 2014] [error] [client 127.0.0.1] Traceback (most recent call last):
[Sun Feb 23 14:47:35 2014] [error] [client 127.0.0.1]   File "/usr/lib/python2.7/dist-packages/django/core/handlers/wsgi.py", line 241, in __call__
[Sun Feb 23 14:47:35 2014] [error] [client 127.0.0.1]     response = self.get_response(request)
[Sun Feb 23 14:47:35 2014] [error] [client 127.0.0.1]   File "/usr/lib/python2.7/dist-packages/django/core/handlers/base.py", line 179, in get_response
[Sun Feb 23 14:47:35 2014] [error] [client 127.0.0.1]     response = self.handle_uncaught_exception(request, resolver, sys.exc_info())
[Sun Feb 23 14:47:35 2014] [error] [client 127.0.0.1]   File "/usr/lib/python2.7/dist-packages/django/core/handlers/base.py", line 221, in handle_uncaught_exception
[Sun Feb 23 14:47:35 2014] [error] [client 127.0.0.1]     return debug.technical_500_response(request, *exc_info)
[Sun Feb 23 14:47:35 2014] [error] [client 127.0.0.1]   File "/usr/lib/python2.7/dist-packages/django/views/debug.py", line 66, in technical_500_response
[Sun Feb 23 14:47:35 2014] [error] [client 127.0.0.1]     html = reporter.get_traceback_html()
[Sun Feb 23 14:47:35 2014] [error] [client 127.0.0.1]   File "/usr/lib/python2.7/dist-packages/django/views/debug.py", line 287, in get_traceback_html
[Sun Feb 23 14:47:35 2014] [error] [client 127.0.0.1]     return t.render(c)
[Sun Feb 23 14:47:35 2014] [error] [client 127.0.0.1]   File "/usr/lib/python2.7/dist-packages/django/template/base.py", line 140, in render
[Sun Feb 23 14:47:35 2014] [error] [client 127.0.0.1]     return self._render(context)
[Sun Feb 23 14:47:35 2014] [error] [client 127.0.0.1]   File "/usr/lib/python2.7/dist-packages/django/template/base.py", line 134, in _render
[Sun Feb 23 14:47:35 2014] [error] [client 127.0.0.1]     return self.nodelist.render(context)
[Sun Feb 23 14:47:35 2014] [error] [client 127.0.0.1]   File "/usr/lib/python2.7/dist-packages/django/template/base.py", line 823, in render
[Sun Feb 23 14:47:35 2014] [error] [client 127.0.0.1]     bit = self.render_node(node, context)
[Sun Feb 23 14:47:35 2014] [error] [client 127.0.0.1]   File "/usr/lib/python2.7/dist-packages/django/template/debug.py", line 74, in render_node
[Sun Feb 23 14:47:35 2014] [error] [client 127.0.0.1]     return node.render(context)
[Sun Feb 23 14:47:35 2014] [error] [client 127.0.0.1]   File "/usr/lib/python2.7/dist-packages/django/template/debug.py", line 84, in render
[Sun Feb 23 14:47:35 2014] [error] [client 127.0.0.1]     output = self.filter_expression.resolve(context)
[Sun Feb 23 14:47:35 2014] [error] [client 127.0.0.1]   File "/usr/lib/python2.7/dist-packages/django/template/base.py", line 599, in resolve
[Sun Feb 23 14:47:35 2014] [error] [client 127.0.0.1]     new_obj = func(obj, *arg_vals)
[Sun Feb 23 14:47:35 2014] [error] [client 127.0.0.1]   File "/usr/lib/python2.7/dist-packages/django/template/defaultfilters.py", line 718, in date
[Sun Feb 23 14:47:35 2014] [error] [client 127.0.0.1]     return format(value, arg)
[Sun Feb 23 14:47:35 2014] [error] [client 127.0.0.1]   File "/usr/lib/python2.7/dist-packages/django/utils/dateformat.py", line 310, in format
[Sun Feb 23 14:47:35 2014] [error] [client 127.0.0.1]     return df.format(format_string)
[Sun Feb 23 14:47:35 2014] [error] [client 127.0.0.1]   File "/usr/lib/python2.7/dist-packages/django/utils/dateformat.py", line 33, in format
[Sun Feb 23 14:47:35 2014] [error] [client 127.0.0.1]     pieces.append(force_unicode(getattr(self, piece)()))
[Sun Feb 23 14:47:35 2014] [error] [client 127.0.0.1]   File "/usr/lib/python2.7/dist-packages/django/utils/dateformat.py", line 214, in r
[Sun Feb 23 14:47:35 2014] [error] [client 127.0.0.1]     return self.format('D, j M Y H:i:s O')
[Sun Feb 23 14:47:35 2014] [error] [client 127.0.0.1]   File "/usr/lib/python2.7/dist-packages/django/utils/dateformat.py", line 33, in format
[Sun Feb 23 14:47:35 2014] [error] [client 127.0.0.1]     pieces.append(force_unicode(getattr(self, piece)()))
[Sun Feb 23 14:47:35 2014] [error] [client 127.0.0.1]   File "/usr/lib/python2.7/dist-packages/django/utils/encoding.py", line 71, in force_unicode
[Sun Feb 23 14:47:35 2014] [error] [client 127.0.0.1]     s = unicode(s)
[Sun Feb 23 14:47:35 2014] [error] [client 127.0.0.1]   File "/usr/lib/python2.7/dist-packages/django/utils/functional.py", line 121, in __unicode_cast
[Sun Feb 23 14:47:35 2014] [error] [client 127.0.0.1]     return func(*self.__args, **self.__kw)
[Sun Feb 23 14:47:35 2014] [error] [client 127.0.0.1]   File "/usr/lib/python2.7/dist-packages/django/utils/translation/__init__.py", line 86, in ugettext
[Sun Feb 23 14:47:35 2014] [error] [client 127.0.0.1]     return _trans.ugettext(message)
[Sun Feb 23 14:47:35 2014] [error] [client 127.0.0.1]   File "/usr/lib/python2.7/dist-packages/django/utils/translation/trans_real.py", line 278, in ugettext
[Sun Feb 23 14:47:35 2014] [error] [client 127.0.0.1]     return do_translate(message, 'ugettext')
[Sun Feb 23 14:47:35 2014] [error] [client 127.0.0.1]   File "/usr/lib/python2.7/dist-packages/django/utils/translation/trans_real.py", line 268, in do_translate
[Sun Feb 23 14:47:35 2014] [error] [client 127.0.0.1]     _default = translation(settings.LANGUAGE_CODE)
[Sun Feb 23 14:47:35 2014] [error] [client 127.0.0.1]   File "/usr/lib/python2.7/dist-packages/django/utils/translation/trans_real.py", line 183, in translation
[Sun Feb 23 14:47:35 2014] [error] [client 127.0.0.1]     default_translation = _fetch(settings.LANGUAGE_CODE)
[Sun Feb 23 14:47:35 2014] [error] [client 127.0.0.1]   File "/usr/lib/python2.7/dist-packages/django/utils/translation/trans_real.py", line 160, in _fetch
[Sun Feb 23 14:47:35 2014] [error] [client 127.0.0.1]     app = import_module(appname)
[Sun Feb 23 14:47:35 2014] [error] [client 127.0.0.1]   File "/usr/lib/python2.7/dist-packages/django/utils/importlib.py", line 35, in import_module
[Sun Feb 23 14:47:35 2014] [error] [client 127.0.0.1]     __import__(name)
[Sun Feb 23 14:47:35 2014] [error] [client 127.0.0.1] ImportError: No module named mainapp
[Sun Feb 23 14:47:44 2014] [error] [client 127.0.0.1] mod_wsgi (pid=8970): Exception occurred processing WSGI script '/home/base_project/engine/wsgi.py'.
[Sun Feb 23 14:47:44 2014] [error] [client 127.0.0.1] Traceback (most recent call last):
[Sun Feb 23 14:47:44 2014] [error] [client 127.0.0.1]   File "/usr/lib/python2.7/dist-packages/django/core/handlers/wsgi.py", line 241, in __call__
[Sun Feb 23 14:47:44 2014] [error] [client 127.0.0.1]     response = self.get_response(request)
[Sun Feb 23 14:47:44 2014] [error] [client 127.0.0.1]   File "/usr/lib/python2.7/dist-packages/django/core/handlers/base.py", line 179, in get_response
[Sun Feb 23 14:47:44 2014] [error] [client 127.0.0.1]     response = self.handle_uncaught_exception(request, resolver, sys.exc_info())
[Sun Feb 23 14:47:44 2014] [error] [client 127.0.0.1]   File "/usr/lib/python2.7/dist-packages/django/core/handlers/base.py", line 221, in handle_uncaught_exception
[Sun Feb 23 14:47:44 2014] [error] [client 127.0.0.1]     return debug.technical_500_response(request, *exc_info)
[Sun Feb 23 14:47:44 2014] [error] [client 127.0.0.1]   File "/usr/lib/python2.7/dist-packages/django/views/debug.py", line 66, in technical_500_response
[Sun Feb 23 14:47:44 2014] [error] [client 127.0.0.1]     html = reporter.get_traceback_html()
[Sun Feb 23 14:47:44 2014] [error] [client 127.0.0.1]   File "/usr/lib/python2.7/dist-packages/django/views/debug.py", line 287, in get_traceback_html
[Sun Feb 23 14:47:44 2014] [error] [client 127.0.0.1]     return t.render(c)
[Sun Feb 23 14:47:44 2014] [error] [client 127.0.0.1]   File "/usr/lib/python2.7/dist-packages/django/template/base.py", line 140, in render
[Sun Feb 23 14:47:44 2014] [error] [client 127.0.0.1]     return self._render(context)
[Sun Feb 23 14:47:44 2014] [error] [client 127.0.0.1]   File "/usr/lib/python2.7/dist-packages/django/template/base.py", line 134, in _render
[Sun Feb 23 14:47:44 2014] [error] [client 127.0.0.1]     return self.nodelist.render(context)
[Sun Feb 23 14:47:44 2014] [error] [client 127.0.0.1]   File "/usr/lib/python2.7/dist-packages/django/template/base.py", line 823, in render
[Sun Feb 23 14:47:44 2014] [error] [client 127.0.0.1]     bit = self.render_node(node, context)
[Sun Feb 23 14:47:44 2014] [error] [client 127.0.0.1]   File "/usr/lib/python2.7/dist-packages/django/template/debug.py", line 74, in render_node
[Sun Feb 23 14:47:44 2014] [error] [client 127.0.0.1]     return node.render(context)
[Sun Feb 23 14:47:44 2014] [error] [client 127.0.0.1]   File "/usr/lib/python2.7/dist-packages/django/template/debug.py", line 84, in render
[Sun Feb 23 14:47:44 2014] [error] [client 127.0.0.1]     output = self.filter_expression.resolve(context)
[Sun Feb 23 14:47:44 2014] [error] [client 127.0.0.1]   File "/usr/lib/python2.7/dist-packages/django/template/base.py", line 599, in resolve
[Sun Feb 23 14:47:44 2014] [error] [client 127.0.0.1]     new_obj = func(obj, *arg_vals)
[Sun Feb 23 14:47:44 2014] [error] [client 127.0.0.1]   File "/usr/lib/python2.7/dist-packages/django/template/defaultfilters.py", line 718, in date
[Sun Feb 23 14:47:44 2014] [error] [client 127.0.0.1]     return format(value, arg)
[Sun Feb 23 14:47:44 2014] [error] [client 127.0.0.1]   File "/usr/lib/python2.7/dist-packages/django/utils/dateformat.py", line 310, in format
[Sun Feb 23 14:47:44 2014] [error] [client 127.0.0.1]     return df.format(format_string)
[Sun Feb 23 14:47:44 2014] [error] [client 127.0.0.1]   File "/usr/lib/python2.7/dist-packages/django/utils/dateformat.py", line 33, in format
[Sun Feb 23 14:47:44 2014] [error] [client 127.0.0.1]     pieces.append(force_unicode(getattr(self, piece)()))
[Sun Feb 23 14:47:44 2014] [error] [client 127.0.0.1]   File "/usr/lib/python2.7/dist-packages/django/utils/dateformat.py", line 214, in r
[Sun Feb 23 14:47:44 2014] [error] [client 127.0.0.1]     return self.format('D, j M Y H:i:s O')
[Sun Feb 23 14:47:44 2014] [error] [client 127.0.0.1]   File "/usr/lib/python2.7/dist-packages/django/utils/dateformat.py", line 33, in format
[Sun Feb 23 14:47:44 2014] [error] [client 127.0.0.1]     pieces.append(force_unicode(getattr(self, piece)()))
[Sun Feb 23 14:47:44 2014] [error] [client 127.0.0.1]   File "/usr/lib/python2.7/dist-packages/django/utils/encoding.py", line 71, in force_unicode
[Sun Feb 23 14:47:44 2014] [error] [client 127.0.0.1]     s = unicode(s)
[Sun Feb 23 14:47:44 2014] [error] [client 127.0.0.1]   File "/usr/lib/python2.7/dist-packages/django/utils/functional.py", line 121, in __unicode_cast
[Sun Feb 23 14:47:44 2014] [error] [client 127.0.0.1]     return func(*self.__args, **self.__kw)
[Sun Feb 23 14:47:44 2014] [error] [client 127.0.0.1]   File "/usr/lib/python2.7/dist-packages/django/utils/translation/__init__.py", line 86, in ugettext
[Sun Feb 23 14:47:44 2014] [error] [client 127.0.0.1]     return _trans.ugettext(message)
[Sun Feb 23 14:47:44 2014] [error] [client 127.0.0.1]   File "/usr/lib/python2.7/dist-packages/django/utils/translation/trans_real.py", line 278, in ugettext
[Sun Feb 23 14:47:44 2014] [error] [client 127.0.0.1]     return do_translate(message, 'ugettext')
[Sun Feb 23 14:47:44 2014] [error] [client 127.0.0.1]   File "/usr/lib/python2.7/dist-packages/django/utils/translation/trans_real.py", line 268, in do_translate
[Sun Feb 23 14:47:44 2014] [error] [client 127.0.0.1]     _default = translation(settings.LANGUAGE_CODE)
[Sun Feb 23 14:47:44 2014] [error] [client 127.0.0.1]   File "/usr/lib/python2.7/dist-packages/django/utils/translation/trans_real.py", line 183, in translation
[Sun Feb 23 14:47:44 2014] [error] [client 127.0.0.1]     default_translation = _fetch(settings.LANGUAGE_CODE)
[Sun Feb 23 14:47:44 2014] [error] [client 127.0.0.1]   File "/usr/lib/python2.7/dist-packages/django/utils/translation/trans_real.py", line 160, in _fetch
[Sun Feb 23 14:47:44 2014] [error] [client 127.0.0.1]     app = import_module(appname)
[Sun Feb 23 14:47:44 2014] [error] [client 127.0.0.1]   File "/usr/lib/python2.7/dist-packages/django/utils/importlib.py", line 35, in import_module
[Sun Feb 23 14:47:44 2014] [error] [client 127.0.0.1]     __import__(name)
[Sun Feb 23 14:47:44 2014] [error] [client 127.0.0.1] ImportError: No module named mainapp
[Sun Feb 23 14:48:51 2014] [error] [client 127.0.0.1] mod_wsgi (pid=8972): Exception occurred processing WSGI script '/home/base_project/engine/wsgi.py'.
[Sun Feb 23 14:48:51 2014] [error] [client 127.0.0.1] Traceback (most recent call last):
[Sun Feb 23 14:48:51 2014] [error] [client 127.0.0.1]   File "/usr/lib/python2.7/dist-packages/django/core/handlers/wsgi.py", line 241, in __call__
[Sun Feb 23 14:48:51 2014] [error] [client 127.0.0.1]     response = self.get_response(request)
[Sun Feb 23 14:48:51 2014] [error] [client 127.0.0.1]   File "/usr/lib/python2.7/dist-packages/django/core/handlers/base.py", line 179, in get_response
[Sun Feb 23 14:48:51 2014] [error] [client 127.0.0.1]     response = self.handle_uncaught_exception(request, resolver, sys.exc_info())
[Sun Feb 23 14:48:51 2014] [error] [client 127.0.0.1]   File "/usr/lib/python2.7/dist-packages/django/core/handlers/base.py", line 221, in handle_uncaught_exception
[Sun Feb 23 14:48:51 2014] [error] [client 127.0.0.1]     return debug.technical_500_response(request, *exc_info)
[Sun Feb 23 14:48:51 2014] [error] [client 127.0.0.1]   File "/usr/lib/python2.7/dist-packages/django/views/debug.py", line 66, in technical_500_response
[Sun Feb 23 14:48:51 2014] [error] [client 127.0.0.1]     html = reporter.get_traceback_html()
[Sun Feb 23 14:48:51 2014] [error] [client 127.0.0.1]   File "/usr/lib/python2.7/dist-packages/django/views/debug.py", line 287, in get_traceback_html
[Sun Feb 23 14:48:51 2014] [error] [client 127.0.0.1]     return t.render(c)
[Sun Feb 23 14:48:51 2014] [error] [client 127.0.0.1]   File "/usr/lib/python2.7/dist-packages/django/template/base.py", line 140, in render
[Sun Feb 23 14:48:51 2014] [error] [client 127.0.0.1]     return self._render(context)
[Sun Feb 23 14:48:51 2014] [error] [client 127.0.0.1]   File "/usr/lib/python2.7/dist-packages/django/template/base.py", line 134, in _render
[Sun Feb 23 14:48:51 2014] [error] [client 127.0.0.1]     return self.nodelist.render(context)
[Sun Feb 23 14:48:51 2014] [error] [client 127.0.0.1]   File "/usr/lib/python2.7/dist-packages/django/template/base.py", line 823, in render
[Sun Feb 23 14:48:51 2014] [error] [client 127.0.0.1]     bit = self.render_node(node, context)
[Sun Feb 23 14:48:51 2014] [error] [client 127.0.0.1]   File "/usr/lib/python2.7/dist-packages/django/template/debug.py", line 74, in render_node
[Sun Feb 23 14:48:51 2014] [error] [client 127.0.0.1]     return node.render(context)
[Sun Feb 23 14:48:51 2014] [error] [client 127.0.0.1]   File "/usr/lib/python2.7/dist-packages/django/template/debug.py", line 84, in render
[Sun Feb 23 14:48:51 2014] [error] [client 127.0.0.1]     output = self.filter_expression.resolve(context)
[Sun Feb 23 14:48:51 2014] [error] [client 127.0.0.1]   File "/usr/lib/python2.7/dist-packages/django/template/base.py", line 599, in resolve
[Sun Feb 23 14:48:51 2014] [error] [client 127.0.0.1]     new_obj = func(obj, *arg_vals)
[Sun Feb 23 14:48:51 2014] [error] [client 127.0.0.1]   File "/usr/lib/python2.7/dist-packages/django/template/defaultfilters.py", line 718, in date
[Sun Feb 23 14:48:51 2014] [error] [client 127.0.0.1]     return format(value, arg)
[Sun Feb 23 14:48:51 2014] [error] [client 127.0.0.1]   File "/usr/lib/python2.7/dist-packages/django/utils/dateformat.py", line 310, in format
[Sun Feb 23 14:48:51 2014] [error] [client 127.0.0.1]     return df.format(format_string)
[Sun Feb 23 14:48:51 2014] [error] [client 127.0.0.1]   File "/usr/lib/python2.7/dist-packages/django/utils/dateformat.py", line 33, in format
[Sun Feb 23 14:48:51 2014] [error] [client 127.0.0.1]     pieces.append(force_unicode(getattr(self, piece)()))
[Sun Feb 23 14:48:51 2014] [error] [client 127.0.0.1]   File "/usr/lib/python2.7/dist-packages/django/utils/dateformat.py", line 214, in r
[Sun Feb 23 14:48:51 2014] [error] [client 127.0.0.1]     return self.format('D, j M Y H:i:s O')
[Sun Feb 23 14:48:51 2014] [error] [client 127.0.0.1]   File "/usr/lib/python2.7/dist-packages/django/utils/dateformat.py", line 33, in format
[Sun Feb 23 14:48:51 2014] [error] [client 127.0.0.1]     pieces.append(force_unicode(getattr(self, piece)()))
[Sun Feb 23 14:48:51 2014] [error] [client 127.0.0.1]   File "/usr/lib/python2.7/dist-packages/django/utils/encoding.py", line 71, in force_unicode
[Sun Feb 23 14:48:51 2014] [error] [client 127.0.0.1]     s = unicode(s)
[Sun Feb 23 14:48:51 2014] [error] [client 127.0.0.1]   File "/usr/lib/python2.7/dist-packages/django/utils/functional.py", line 121, in __unicode_cast
[Sun Feb 23 14:48:51 2014] [error] [client 127.0.0.1]     return func(*self.__args, **self.__kw)
[Sun Feb 23 14:48:51 2014] [error] [client 127.0.0.1]   File "/usr/lib/python2.7/dist-packages/django/utils/translation/__init__.py", line 86, in ugettext
[Sun Feb 23 14:48:51 2014] [error] [client 127.0.0.1]     return _trans.ugettext(message)
[Sun Feb 23 14:48:51 2014] [error] [client 127.0.0.1]   File "/usr/lib/python2.7/dist-packages/django/utils/translation/trans_real.py", line 278, in ugettext
[Sun Feb 23 14:48:51 2014] [error] [client 127.0.0.1]     return do_translate(message, 'ugettext')
[Sun Feb 23 14:48:51 2014] [error] [client 127.0.0.1]   File "/usr/lib/python2.7/dist-packages/django/utils/translation/trans_real.py", line 268, in do_translate
[Sun Feb 23 14:48:51 2014] [error] [client 127.0.0.1]     _default = translation(settings.LANGUAGE_CODE)
[Sun Feb 23 14:48:51 2014] [error] [client 127.0.0.1]   File "/usr/lib/python2.7/dist-packages/django/utils/translation/trans_real.py", line 183, in translation
[Sun Feb 23 14:48:51 2014] [error] [client 127.0.0.1]     default_translation = _fetch(settings.LANGUAGE_CODE)
[Sun Feb 23 14:48:51 2014] [error] [client 127.0.0.1]   File "/usr/lib/python2.7/dist-packages/django/utils/translation/trans_real.py", line 160, in _fetch
[Sun Feb 23 14:48:51 2014] [error] [client 127.0.0.1]     app = import_module(appname)
[Sun Feb 23 14:48:51 2014] [error] [client 127.0.0.1]   File "/usr/lib/python2.7/dist-packages/django/utils/importlib.py", line 35, in import_module
[Sun Feb 23 14:48:51 2014] [error] [client 127.0.0.1]     __import__(name)
[Sun Feb 23 14:48:51 2014] [error] [client 127.0.0.1] ImportError: No module named mainapp
[Sun Feb 23 14:49:17 2014] [error] [client 127.0.0.1] mod_wsgi (pid=9092): Exception occurred processing WSGI script '/home/base_project/engine/wsgi.py'.
[Sun Feb 23 14:49:17 2014] [error] [client 127.0.0.1] Traceback (most recent call last):
[Sun Feb 23 14:49:17 2014] [error] [client 127.0.0.1]   File "/usr/lib/python2.7/dist-packages/django/core/handlers/wsgi.py", line 241, in __call__
[Sun Feb 23 14:49:17 2014] [error] [client 127.0.0.1]     response = self.get_response(request)
[Sun Feb 23 14:49:17 2014] [error] [client 127.0.0.1]   File "/usr/lib/python2.7/dist-packages/django/core/handlers/base.py", line 179, in get_response
[Sun Feb 23 14:49:17 2014] [error] [client 127.0.0.1]     response = self.handle_uncaught_exception(request, resolver, sys.exc_info())
[Sun Feb 23 14:49:17 2014] [error] [client 127.0.0.1]   File "/usr/lib/python2.7/dist-packages/django/core/handlers/base.py", line 221, in handle_uncaught_exception
[Sun Feb 23 14:49:17 2014] [error] [client 127.0.0.1]     return debug.technical_500_response(request, *exc_info)
[Sun Feb 23 14:49:17 2014] [error] [client 127.0.0.1]   File "/usr/lib/python2.7/dist-packages/django/views/debug.py", line 66, in technical_500_response
[Sun Feb 23 14:49:17 2014] [error] [client 127.0.0.1]     html = reporter.get_traceback_html()
[Sun Feb 23 14:49:17 2014] [error] [client 127.0.0.1]   File "/usr/lib/python2.7/dist-packages/django/views/debug.py", line 287, in get_traceback_html
[Sun Feb 23 14:49:17 2014] [error] [client 127.0.0.1]     return t.render(c)
[Sun Feb 23 14:49:17 2014] [error] [client 127.0.0.1]   File "/usr/lib/python2.7/dist-packages/django/template/base.py", line 140, in render
[Sun Feb 23 14:49:17 2014] [error] [client 127.0.0.1]     return self._render(context)
[Sun Feb 23 14:49:17 2014] [error] [client 127.0.0.1]   File "/usr/lib/python2.7/dist-packages/django/template/base.py", line 134, in _render
[Sun Feb 23 14:49:17 2014] [error] [client 127.0.0.1]     return self.nodelist.render(context)
[Sun Feb 23 14:49:17 2014] [error] [client 127.0.0.1]   File "/usr/lib/python2.7/dist-packages/django/template/base.py", line 823, in render
[Sun Feb 23 14:49:17 2014] [error] [client 127.0.0.1]     bit = self.render_node(node, context)
[Sun Feb 23 14:49:17 2014] [error] [client 127.0.0.1]   File "/usr/lib/python2.7/dist-packages/django/template/debug.py", line 74, in render_node
[Sun Feb 23 14:49:17 2014] [error] [client 127.0.0.1]     return node.render(context)
[Sun Feb 23 14:49:17 2014] [error] [client 127.0.0.1]   File "/usr/lib/python2.7/dist-packages/django/template/debug.py", line 84, in render
[Sun Feb 23 14:49:17 2014] [error] [client 127.0.0.1]     output = self.filter_expression.resolve(context)
[Sun Feb 23 14:49:17 2014] [error] [client 127.0.0.1]   File "/usr/lib/python2.7/dist-packages/django/template/base.py", line 599, in resolve
[Sun Feb 23 14:49:17 2014] [error] [client 127.0.0.1]     new_obj = func(obj, *arg_vals)
[Sun Feb 23 14:49:17 2014] [error] [client 127.0.0.1]   File "/usr/lib/python2.7/dist-packages/django/template/defaultfilters.py", line 718, in date
[Sun Feb 23 14:49:17 2014] [error] [client 127.0.0.1]     return format(value, arg)
[Sun Feb 23 14:49:17 2014] [error] [client 127.0.0.1]   File "/usr/lib/python2.7/dist-packages/django/utils/dateformat.py", line 310, in format
[Sun Feb 23 14:49:17 2014] [error] [client 127.0.0.1]     return df.format(format_string)
[Sun Feb 23 14:49:17 2014] [error] [client 127.0.0.1]   File "/usr/lib/python2.7/dist-packages/django/utils/dateformat.py", line 33, in format
[Sun Feb 23 14:49:17 2014] [error] [client 127.0.0.1]     pieces.append(force_unicode(getattr(self, piece)()))
[Sun Feb 23 14:49:17 2014] [error] [client 127.0.0.1]   File "/usr/lib/python2.7/dist-packages/django/utils/dateformat.py", line 214, in r
[Sun Feb 23 14:49:17 2014] [error] [client 127.0.0.1]     return self.format('D, j M Y H:i:s O')
[Sun Feb 23 14:49:17 2014] [error] [client 127.0.0.1]   File "/usr/lib/python2.7/dist-packages/django/utils/dateformat.py", line 33, in format
[Sun Feb 23 14:49:17 2014] [error] [client 127.0.0.1]     pieces.append(force_unicode(getattr(self, piece)()))
[Sun Feb 23 14:49:17 2014] [error] [client 127.0.0.1]   File "/usr/lib/python2.7/dist-packages/django/utils/encoding.py", line 71, in force_unicode
[Sun Feb 23 14:49:17 2014] [error] [client 127.0.0.1]     s = unicode(s)
[Sun Feb 23 14:49:17 2014] [error] [client 127.0.0.1]   File "/usr/lib/python2.7/dist-packages/django/utils/functional.py", line 121, in __unicode_cast
[Sun Feb 23 14:49:17 2014] [error] [client 127.0.0.1]     return func(*self.__args, **self.__kw)
[Sun Feb 23 14:49:17 2014] [error] [client 127.0.0.1]   File "/usr/lib/python2.7/dist-packages/django/utils/translation/__init__.py", line 86, in ugettext
[Sun Feb 23 14:49:17 2014] [error] [client 127.0.0.1]     return _trans.ugettext(message)
[Sun Feb 23 14:49:17 2014] [error] [client 127.0.0.1]   File "/usr/lib/python2.7/dist-packages/django/utils/translation/trans_real.py", line 278, in ugettext
[Sun Feb 23 14:49:17 2014] [error] [client 127.0.0.1]     return do_translate(message, 'ugettext')
[Sun Feb 23 14:49:17 2014] [error] [client 127.0.0.1]   File "/usr/lib/python2.7/dist-packages/django/utils/translation/trans_real.py", line 268, in do_translate
[Sun Feb 23 14:49:17 2014] [error] [client 127.0.0.1]     _default = translation(settings.LANGUAGE_CODE)
[Sun Feb 23 14:49:17 2014] [error] [client 127.0.0.1]   File "/usr/lib/python2.7/dist-packages/django/utils/translation/trans_real.py", line 183, in translation
[Sun Feb 23 14:49:17 2014] [error] [client 127.0.0.1]     default_translation = _fetch(settings.LANGUAGE_CODE)
[Sun Feb 23 14:49:17 2014] [error] [client 127.0.0.1]   File "/usr/lib/python2.7/dist-packages/django/utils/translation/trans_real.py", line 160, in _fetch
[Sun Feb 23 14:49:17 2014] [error] [client 127.0.0.1]     app = import_module(appname)
[Sun Feb 23 14:49:17 2014] [error] [client 127.0.0.1]   File "/usr/lib/python2.7/dist-packages/django/utils/importlib.py", line 35, in import_module
[Sun Feb 23 14:49:17 2014] [error] [client 127.0.0.1]     __import__(name)
[Sun Feb 23 14:49:17 2014] [error] [client 127.0.0.1] ImportError: No module named mainapp
[Sun Feb 23 14:52:13 2014] [error] [client 127.0.0.1] mod_wsgi (pid=9210): Exception occurred processing WSGI script '/home/base_project/engine/wsgi.py'.
[Sun Feb 23 14:52:13 2014] [error] [client 127.0.0.1] Traceback (most recent call last):
[Sun Feb 23 14:52:13 2014] [error] [client 127.0.0.1]   File "/usr/lib/python2.7/dist-packages/django/core/handlers/wsgi.py", line 241, in __call__
[Sun Feb 23 14:52:13 2014] [error] [client 127.0.0.1]     response = self.get_response(request)
[Sun Feb 23 14:52:13 2014] [error] [client 127.0.0.1]   File "/usr/lib/python2.7/dist-packages/django/core/handlers/base.py", line 179, in get_response
[Sun Feb 23 14:52:13 2014] [error] [client 127.0.0.1]     response = self.handle_uncaught_exception(request, resolver, sys.exc_info())
[Sun Feb 23 14:52:13 2014] [error] [client 127.0.0.1]   File "/usr/lib/python2.7/dist-packages/django/core/handlers/base.py", line 221, in handle_uncaught_exception
[Sun Feb 23 14:52:13 2014] [error] [client 127.0.0.1]     return debug.technical_500_response(request, *exc_info)
[Sun Feb 23 14:52:13 2014] [error] [client 127.0.0.1]   File "/usr/lib/python2.7/dist-packages/django/views/debug.py", line 66, in technical_500_response
[Sun Feb 23 14:52:13 2014] [error] [client 127.0.0.1]     html = reporter.get_traceback_html()
[Sun Feb 23 14:52:13 2014] [error] [client 127.0.0.1]   File "/usr/lib/python2.7/dist-packages/django/views/debug.py", line 287, in get_traceback_html
[Sun Feb 23 14:52:13 2014] [error] [client 127.0.0.1]     return t.render(c)
[Sun Feb 23 14:52:13 2014] [error] [client 127.0.0.1]   File "/usr/lib/python2.7/dist-packages/django/template/base.py", line 140, in render
[Sun Feb 23 14:52:13 2014] [error] [client 127.0.0.1]     return self._render(context)
[Sun Feb 23 14:52:13 2014] [error] [client 127.0.0.1]   File "/usr/lib/python2.7/dist-packages/django/template/base.py", line 134, in _render
[Sun Feb 23 14:52:13 2014] [error] [client 127.0.0.1]     return self.nodelist.render(context)
[Sun Feb 23 14:52:13 2014] [error] [client 127.0.0.1]   File "/usr/lib/python2.7/dist-packages/django/template/base.py", line 823, in render
[Sun Feb 23 14:52:13 2014] [error] [client 127.0.0.1]     bit = self.render_node(node, context)
[Sun Feb 23 14:52:13 2014] [error] [client 127.0.0.1]   File "/usr/lib/python2.7/dist-packages/django/template/debug.py", line 74, in render_node
[Sun Feb 23 14:52:13 2014] [error] [client 127.0.0.1]     return node.render(context)
[Sun Feb 23 14:52:13 2014] [error] [client 127.0.0.1]   File "/usr/lib/python2.7/dist-packages/django/template/debug.py", line 84, in render
[Sun Feb 23 14:52:13 2014] [error] [client 127.0.0.1]     output = self.filter_expression.resolve(context)
[Sun Feb 23 14:52:13 2014] [error] [client 127.0.0.1]   File "/usr/lib/python2.7/dist-packages/django/template/base.py", line 599, in resolve
[Sun Feb 23 14:52:13 2014] [error] [client 127.0.0.1]     new_obj = func(obj, *arg_vals)
[Sun Feb 23 14:52:13 2014] [error] [client 127.0.0.1]   File "/usr/lib/python2.7/dist-packages/django/template/defaultfilters.py", line 718, in date
[Sun Feb 23 14:52:13 2014] [error] [client 127.0.0.1]     return format(value, arg)
[Sun Feb 23 14:52:13 2014] [error] [client 127.0.0.1]   File "/usr/lib/python2.7/dist-packages/django/utils/dateformat.py", line 310, in format
[Sun Feb 23 14:52:13 2014] [error] [client 127.0.0.1]     return df.format(format_string)
[Sun Feb 23 14:52:13 2014] [error] [client 127.0.0.1]   File "/usr/lib/python2.7/dist-packages/django/utils/dateformat.py", line 33, in format
[Sun Feb 23 14:52:13 2014] [error] [client 127.0.0.1]     pieces.append(force_unicode(getattr(self, piece)()))
[Sun Feb 23 14:52:13 2014] [error] [client 127.0.0.1]   File "/usr/lib/python2.7/dist-packages/django/utils/dateformat.py", line 214, in r
[Sun Feb 23 14:52:13 2014] [error] [client 127.0.0.1]     return self.format('D, j M Y H:i:s O')
[Sun Feb 23 14:52:13 2014] [error] [client 127.0.0.1]   File "/usr/lib/python2.7/dist-packages/django/utils/dateformat.py", line 33, in format
[Sun Feb 23 14:52:13 2014] [error] [client 127.0.0.1]     pieces.append(force_unicode(getattr(self, piece)()))
[Sun Feb 23 14:52:13 2014] [error] [client 127.0.0.1]   File "/usr/lib/python2.7/dist-packages/django/utils/encoding.py", line 71, in force_unicode
[Sun Feb 23 14:52:13 2014] [error] [client 127.0.0.1]     s = unicode(s)
[Sun Feb 23 14:52:13 2014] [error] [client 127.0.0.1]   File "/usr/lib/python2.7/dist-packages/django/utils/functional.py", line 121, in __unicode_cast
[Sun Feb 23 14:52:13 2014] [error] [client 127.0.0.1]     return func(*self.__args, **self.__kw)
[Sun Feb 23 14:52:13 2014] [error] [client 127.0.0.1]   File "/usr/lib/python2.7/dist-packages/django/utils/translation/__init__.py", line 86, in ugettext
[Sun Feb 23 14:52:13 2014] [error] [client 127.0.0.1]     return _trans.ugettext(message)
[Sun Feb 23 14:52:13 2014] [error] [client 127.0.0.1]   File "/usr/lib/python2.7/dist-packages/django/utils/translation/trans_real.py", line 278, in ugettext
[Sun Feb 23 14:52:13 2014] [error] [client 127.0.0.1]     return do_translate(message, 'ugettext')
[Sun Feb 23 14:52:13 2014] [error] [client 127.0.0.1]   File "/usr/lib/python2.7/dist-packages/django/utils/translation/trans_real.py", line 268, in do_translate
[Sun Feb 23 14:52:13 2014] [error] [client 127.0.0.1]     _default = translation(settings.LANGUAGE_CODE)
[Sun Feb 23 14:52:13 2014] [error] [client 127.0.0.1]   File "/usr/lib/python2.7/dist-packages/django/utils/translation/trans_real.py", line 183, in translation
[Sun Feb 23 14:52:13 2014] [error] [client 127.0.0.1]     default_translation = _fetch(settings.LANGUAGE_CODE)
[Sun Feb 23 14:52:13 2014] [error] [client 127.0.0.1]   File "/usr/lib/python2.7/dist-packages/django/utils/translation/trans_real.py", line 160, in _fetch
[Sun Feb 23 14:52:13 2014] [error] [client 127.0.0.1]     app = import_module(appname)
[Sun Feb 23 14:52:13 2014] [error] [client 127.0.0.1]   File "/usr/lib/python2.7/dist-packages/django/utils/importlib.py", line 35, in import_module
[Sun Feb 23 14:52:13 2014] [error] [client 127.0.0.1]     __import__(name)
[Sun Feb 23 14:52:13 2014] [error] [client 127.0.0.1] ImportError: No module named mainapp
